Workbook

Sheet Калькулятор
A1: Калькулятор очков FINA (World Aquatics Points)
A2: Всё выбирается из списков в серых ячейках. Можно и напечатать число в ячейку.
A4: Бассейн | B4: 25 м
A5: Пол | B5: Мужчины
A6: Дистанция | B6: 100 м вольный стиль
A7: Минуты | B7: 0
A8: Секунды | B8: 50
A9: Сотые | B9: 12
A11: Время | B11: =IF(B13="","",IF(INT(ROUND(B13*100,0)/6000)>0,INT(ROUND(B13*100,0)/6000)&":"&RIGHT("0"&INT(MOD(ROUND(B13*100,0),6000)/100),2),INT(MOD(ROUND(B13*100,0),6000)/100))&"."&RIGHT("0"&MOD(ROUND(B13*100,0),100),2)) -> 50.12
A12: Базовое время, с | B12: =SUMIFS('Базовые времена'!$D$2:$D$71,'Базовые времена'!$A$2:$A$71,$B$4,'Базовые времена'!$B$2:$B$71,$B$5,'Базовые времена'!$C$2:$C$71,$B$6) -> 44.84 | C12: =IF(B12=0,"Такой дистанции нет в этом бассейне","")
A13: Время, с | B13: =IF(N(B7)*60+N(B8)+N(B9)/100<=0,"",N(B7)*60+N(B8)+N(B9)/100) -> 50.12
A14: Очки FINA | B14: =IF(OR(B12=0,B13=""),"",ROUNDDOWN(1000*(B12/B13)^3,0)) -> 716
A16: Обратный расчёт
A17: Нужные очки | B17: 700
A18: Нужное время | B18: =IF(C18="","",IF(INT(ROUND(C18*100,0)/6000)>0,INT(ROUND(C18*100,0)/6000)&":"&RIGHT("0"&INT(MOD(ROUND(C18*100,0),6000)/100),2),INT(MOD(ROUND(C18*100,0),6000)/100))&"."&RIGHT("0"&MOD(ROUND(C18*100,0),100),2)) -> 50.50 | C18: =IF(OR(B12=0,N(B17)<=0),"",ROUNDDOWN(B12/(B17/1000)^(1/3)+0.000000001,2)) -> 50.5
A20: Формула: очки = 1000 × (базовое время / время)³, дробная часть отбрасывается.
A21: Сайт: https://fina.borozdov.ru — тот же расчёт.

Sheet Протокол
A1: Спортсмен | B1: Бассейн | C1: Пол | D1: Дистанция | E1: Время | F1: Очки FINA | G1: Базовое время, с | H1: Время, с
A2: Иванов Иван | B2: 25 м | C2: Мужчины | D2: 100 м вольный стиль | E2: 50.12 | F2: =IF(OR(G2="",H2="",N(G2)=0,N(H2)<=0),"",ROUNDDOWN(1000*(G2/H2)^3,0)) -> 716 | G2: =IF(D2="","",SUMIFS('Базовые времена'!$D$2:$D$71,'Базовые времена'!$A$2:$A$71,B2,'Базовые времена'!$B$2:$B$71,C2,'Базовые времена'!$C$2:$C$71,D2)) -> 44.84 | H2: =IF(E2="","",IF(ISNUMBER(E2),IF(E2<1,E2*86400,E2),IFERROR(IF(ISNUMBER(FIND(":",SUBSTITUTE(TRIM(E2),",","."))),VALUE(LEFT(SUBSTITUTE(TRIM(E2),",","."),FIND(":",SUBSTITUTE(TRIM(E2),",","."))-1))*60+_xlfn.NUMBERVALUE(MID(SUBSTITUTE(TRIM(E2),",","."),FIND(":",SUBSTITUTE(TRIM(E2),",","."))+1,99),"."),_xlfn.NUMBERVALUE(SUBSTITUTE(TRIM(E2),",","."),".")),0))) -> 50.12
A3: Петрова Анна | B3: 50 м | C3: Женщины | D3: 200 м комплекс | E3: 2:21.40 | F3: =IF(OR(G3="",H3="",N(G3)=0,N(H3)<=0),"",ROUNDDOWN(1000*(G3/H3)^3,0)) -> 702 | G3: =IF(D3="","",SUMIFS('Базовые времена'!$D$2:$D$71,'Базовые времена'!$A$2:$A$71,B3,'Базовые времена'!$B$2:$B$71,C3,'Базовые времена'!$C$2:$C$71,D3)) -> 125.7 | H3: =IF(E3="","",IF(ISNUMBER(E3),IF(E3<1,E3*86400,E3),IFERROR(IF(ISNUMBER(FIND(":",SUBSTITUTE(TRIM(E3),",","."))),VALUE(LEFT(SUBSTITUTE(TRIM(E3),",","."),FIND(":",SUBSTITUTE(TRIM(E3),",","."))-1))*60+_xlfn.NUMBERVALUE(MID(SUBSTITUTE(TRIM(E3),",","."),FIND(":",SUBSTITUTE(TRIM(E3),",","."))+1,99),"."),_xlfn.NUMBERVALUE(SUBSTITUTE(TRIM(E3),",","."),".")),0))) -> 141.4
F4: =IF(OR(G4="",H4="",N(G4)=0,N(H4)<=0),"",ROUNDDOWN(1000*(G4/H4)^3,0)) | G4: =IF(D4="","",SUMIFS('Базовые времена'!$D$2:$D$71,'Базовые времена'!$A$2:$A$71,B4,'Базовые времена'!$B$2:$B$71,C4,'Базовые времена'!$C$2:$C$71,D4)) | H4: =IF(E4="","",IF(ISNUMBER(E4),IF(E4<1,E4*86400,E4),IFERROR(IF(ISNUMBER(FIND(":",SUBSTITUTE(TRIM(E4),",","."))),VALUE(LEFT(SUBSTITUTE(TRIM(E4),",","."),FIND(":",SUBSTITUTE(TRIM(E4),",","."))-1))*60+_xlfn.NUMBERVALUE(MID(SUBSTITUTE(TRIM(E4),",","."),FIND(":",SUBSTITUTE(TRIM(E4),",","."))+1,99),"."),_xlfn.NUMBERVALUE(SUBSTITUTE(TRIM(E4),",","."),".")),0)))
F5: =IF(OR(G5="",H5="",N(G5)=0,N(H5)<=0),"",ROUNDDOWN(1000*(G5/H5)^3,0)) | G5: =IF(D5="","",SUMIFS('Базовые времена'!$D$2:$D$71,'Базовые времена'!$A$2:$A$71,B5,'Базовые времена'!$B$2:$B$71,C5,'Базовые времена'!$C$2:$C$71,D5)) | H5: =IF(E5="","",IF(ISNUMBER(E5),IF(E5<1,E5*86400,E5),IFERROR(IF(ISNUMBER(FIND(":",SUBSTITUTE(TRIM(E5),",","."))),VALUE(LEFT(SUBSTITUTE(TRIM(E5),",","."),FIND(":",SUBSTITUTE(TRIM(E5),",","."))-1))*60+_xlfn.NUMBERVALUE(MID(SUBSTITUTE(TRIM(E5),",","."),FIND(":",SUBSTITUTE(TRIM(E5),",","."))+1,99),"."),_xlfn.NUMBERVALUE(SUBSTITUTE(TRIM(E5),",","."),".")),0)))
F6: =IF(OR(G6="",H6="",N(G6)=0,N(H6)<=0),"",ROUNDDOWN(1000*(G6/H6)^3,0)) | G6: =IF(D6="","",SUMIFS('Базовые времена'!$D$2:$D$71,'Базовые времена'!$A$2:$A$71,B6,'Базовые времена'!$B$2:$B$71,C6,'Базовые времена'!$C$2:$C$71,D6)) | H6: =IF(E6="","",IF(ISNUMBER(E6),IF(E6<1,E6*86400,E6),IFERROR(IF(ISNUMBER(FIND(":",SUBSTITUTE(TRIM(E6),",","."))),VALUE(LEFT(SUBSTITUTE(TRIM(E6),",","."),FIND(":",SUBSTITUTE(TRIM(E6),",","."))-1))*60+_xlfn.NUMBERVALUE(MID(SUBSTITUTE(TRIM(E6),",","."),FIND(":",SUBSTITUTE(TRIM(E6),",","."))+1,99),"."),_xlfn.NUMBERVALUE(SUBSTITUTE(TRIM(E6),",","."),".")),0)))
F7: =IF(OR(G7="",H7="",N(G7)=0,N(H7)<=0),"",ROUNDDOWN(1000*(G7/H7)^3,0)) | G7: =IF(D7="","",SUMIFS('Базовые времена'!$D$2:$D$71,'Базовые времена'!$A$2:$A$71,B7,'Базовые времена'!$B$2:$B$71,C7,'Базовые времена'!$C$2:$C$71,D7)) | H7: =IF(E7="","",IF(ISNUMBER(E7),IF(E7<1,E7*86400,E7),IFERROR(IF(ISNUMBER(FIND(":",SUBSTITUTE(TRIM(E7),",","."))),VALUE(LEFT(SUBSTITUTE(TRIM(E7),",","."),FIND(":",SUBSTITUTE(TRIM(E7),",","."))-1))*60+_xlfn.NUMBERVALUE(MID(SUBSTITUTE(TRIM(E7),",","."),FIND(":",SUBSTITUTE(TRIM(E7),",","."))+1,99),"."),_xlfn.NUMBERVALUE(SUBSTITUTE(TRIM(E7),",","."),".")),0)))
F8: =IF(OR(G8="",H8="",N(G8)=0,N(H8)<=0),"",ROUNDDOWN(1000*(G8/H8)^3,0)) | G8: =IF(D8="","",SUMIFS('Базовые времена'!$D$2:$D$71,'Базовые времена'!$A$2:$A$71,B8,'Базовые времена'!$B$2:$B$71,C8,'Базовые времена'!$C$2:$C$71,D8)) | H8: =IF(E8="","",IF(ISNUMBER(E8),IF(E8<1,E8*86400,E8),IFERROR(IF(ISNUMBER(FIND(":",SUBSTITUTE(TRIM(E8),",","."))),VALUE(LEFT(SUBSTITUTE(TRIM(E8),",","."),FIND(":",SUBSTITUTE(TRIM(E8),",","."))-1))*60+_xlfn.NUMBERVALUE(MID(SUBSTITUTE(TRIM(E8),",","."),FIND(":",SUBSTITUTE(TRIM(E8),",","."))+1,99),"."),_xlfn.NUMBERVALUE(SUBSTITUTE(TRIM(E8),",","."),".")),0)))
F9: =IF(OR(G9="",H9="",N(G9)=0,N(H9)<=0),"",ROUNDDOWN(1000*(G9/H9)^3,0)) | G9: =IF(D9="","",SUMIFS('Базовые времена'!$D$2:$D$71,'Базовые времена'!$A$2:$A$71,B9,'Базовые времена'!$B$2:$B$71,C9,'Базовые времена'!$C$2:$C$71,D9)) | H9: =IF(E9="","",IF(ISNUMBER(E9),IF(E9<1,E9*86400,E9),IFERROR(IF(ISNUMBER(FIND(":",SUBSTITUTE(TRIM(E9),",","."))),VALUE(LEFT(SUBSTITUTE(TRIM(E9),",","."),FIND(":",SUBSTITUTE(TRIM(E9),",","."))-1))*60+_xlfn.NUMBERVALUE(MID(SUBSTITUTE(TRIM(E9),",","."),FIND(":",SUBSTITUTE(TRIM(E9),",","."))+1,99),"."),_xlfn.NUMBERVALUE(SUBSTITUTE(TRIM(E9),",","."),".")),0)))
F10: =IF(OR(G10="",H10="",N(G10)=0,N(H10)<=0),"",ROUNDDOWN(1000*(G10/H10)^3,0)) | G10: =IF(D10="","",SUMIFS('Базовые времена'!$D$2:$D$71,'Базовые времена'!$A$2:$A$71,B10,'Базовые времена'!$B$2:$B$71,C10,'Базовые времена'!$C$2:$C$71,D10)) | H10: =IF(E10="","",IF(ISNUMBER(E10),IF(E10<1,E10*86400,E10),IFERROR(IF(ISNUMBER(FIND(":",SUBSTITUTE(TRIM(E10),",","."))),VALUE(LEFT(SUBSTITUTE(TRIM(E10),",","."),FIND(":",SUBSTITUTE(TRIM(E10),",","."))-1))*60+_xlfn.NUMBERVALUE(MID(SUBSTITUTE(TRIM(E10),",","."),FIND(":",SUBSTITUTE(TRIM(E10),",","."))+1,99),"."),_xlfn.NUMBERVALUE(SUBSTITUTE(TRIM(E10),",","."),".")),0)))
F11: =IF(OR(G11="",H11="",N(G11)=0,N(H11)<=0),"",ROUNDDOWN(1000*(G11/H11)^3,0)) | G11: =IF(D11="","",SUMIFS('Базовые времена'!$D$2:$D$71,'Базовые времена'!$A$2:$A$71,B11,'Базовые времена'!$B$2:$B$71,C11,'Базовые времена'!$C$2:$C$71,D11)) | H11: =IF(E11="","",IF(ISNUMBER(E11),IF(E11<1,E11*86400,E11),IFERROR(IF(ISNUMBER(FIND(":",SUBSTITUTE(TRIM(E11),",","."))),VALUE(LEFT(SUBSTITUTE(TRIM(E11),",","."),FIND(":",SUBSTITUTE(TRIM(E11),",","."))-1))*60+_xlfn.NUMBERVALUE(MID(SUBSTITUTE(TRIM(E11),",","."),FIND(":",SUBSTITUTE(TRIM(E11),",","."))+1,99),"."),_xlfn.NUMBERVALUE(SUBSTITUTE(TRIM(E11),",","."),".")),0)))
F12: =IF(OR(G12="",H12="",N(G12)=0,N(H12)<=0),"",ROUNDDOWN(1000*(G12/H12)^3,0)) | G12: =IF(D12="","",SUMIFS('Базовые времена'!$D$2:$D$71,'Базовые времена'!$A$2:$A$71,B12,'Базовые времена'!$B$2:$B$71,C12,'Базовые времена'!$C$2:$C$71,D12)) | H12: =IF(E12="","",IF(ISNUMBER(E12),IF(E12<1,E12*86400,E12),IFERROR(IF(ISNUMBER(FIND(":",SUBSTITUTE(TRIM(E12),",","."))),VALUE(LEFT(SUBSTITUTE(TRIM(E12),",","."),FIND(":",SUBSTITUTE(TRIM(E12),",","."))-1))*60+_xlfn.NUMBERVALUE(MID(SUBSTITUTE(TRIM(E12),",","."),FIND(":",SUBSTITUTE(TRIM(E12),",","."))+1,99),"."),_xlfn.NUMBERVALUE(SUBSTITUTE(TRIM(E12),",","."),".")),0)))
F13: =IF(OR(G13="",H13="",N(G13)=0,N(H13)<=0),"",ROUNDDOWN(1000*(G13/H13)^3,0)) | G13: =IF(D13="","",SUMIFS('Базовые времена'!$D$2:$D$71,'Базовые времена'!$A$2:$A$71,B13,'Базовые времена'!$B$2:$B$71,C13,'Базовые времена'!$C$2:$C$71,D13)) | H13: =IF(E13="","",IF(ISNUMBER(E13),IF(E13<1,E13*86400,E13),IFERROR(IF(ISNUMBER(FIND(":",SUBSTITUTE(TRIM(E13),",","."))),VALUE(LEFT(SUBSTITUTE(TRIM(E13),",","."),FIND(":",SUBSTITUTE(TRIM(E13),",","."))-1))*60+_xlfn.NUMBERVALUE(MID(SUBSTITUTE(TRIM(E13),",","."),FIND(":",SUBSTITUTE(TRIM(E13),",","."))+1,99),"."),_xlfn.NUMBERVALUE(SUBSTITUTE(TRIM(E13),",","."),".")),0)))
F14: =IF(OR(G14="",H14="",N(G14)=0,N(H14)<=0),"",ROUNDDOWN(1000*(G14/H14)^3,0)) | G14: =IF(D14="","",SUMIFS('Базовые времена'!$D$2:$D$71,'Базовые времена'!$A$2:$A$71,B14,'Базовые времена'!$B$2:$B$71,C14,'Базовые времена'!$C$2:$C$71,D14)) | H14: =IF(E14="","",IF(ISNUMBER(E14),IF(E14<1,E14*86400,E14),IFERROR(IF(ISNUMBER(FIND(":",SUBSTITUTE(TRIM(E14),",","."))),VALUE(LEFT(SUBSTITUTE(TRIM(E14),",","."),FIND(":",SUBSTITUTE(TRIM(E14),",","."))-1))*60+_xlfn.NUMBERVALUE(MID(SUBSTITUTE(TRIM(E14),",","."),FIND(":",SUBSTITUTE(TRIM(E14),",","."))+1,99),"."),_xlfn.NUMBERVALUE(SUBSTITUTE(TRIM(E14),",","."),".")),0)))
F15: =IF(OR(G15="",H15="",N(G15)=0,N(H15)<=0),"",ROUNDDOWN(1000*(G15/H15)^3,0)) | G15: =IF(D15="","",SUMIFS('Базовые времена'!$D$2:$D$71,'Базовые времена'!$A$2:$A$71,B15,'Базовые времена'!$B$2:$B$71,C15,'Базовые времена'!$C$2:$C$71,D15)) | H15: =IF(E15="","",IF(ISNUMBER(E15),IF(E15<1,E15*86400,E15),IFERROR(IF(ISNUMBER(FIND(":",SUBSTITUTE(TRIM(E15),",","."))),VALUE(LEFT(SUBSTITUTE(TRIM(E15),",","."),FIND(":",SUBSTITUTE(TRIM(E15),",","."))-1))*60+_xlfn.NUMBERVALUE(MID(SUBSTITUTE(TRIM(E15),",","."),FIND(":",SUBSTITUTE(TRIM(E15),",","."))+1,99),"."),_xlfn.NUMBERVALUE(SUBSTITUTE(TRIM(E15),",","."),".")),0)))
... F501: =IF(OR(G501="",H501="",N(G501)=0,N(H501)<=0),"",ROUNDDOWN(1000*(G501/H501)^3,0)) | G501: =IF(D501="","",SUMIFS('Базовые времена'!$D$2:$D$71,'Базовые времена'!$A$2:$A$71,B501,'Базовые времена'!$B$2:$B$71,C501,'Базовые времена'!$C$2:$C$71,D501)) | H501: =IF(E501="","",IF(ISNUMBER(E501),IF(E501<1,E501*86400,E501),IFERROR(IF(ISNUMBER(FIND(":",SUBSTITUTE(TRIM(E501),",","."))),VALUE(LEFT(SUBSTITUTE(TRIM(E501),",","."),FIND(":",SUBSTITUTE(TRIM(E501),",","."))-1))*60+_xlfn.NUMBERVALUE(MID(SUBSTITUTE(TRIM(E501),",","."),FIND(":",SUBSTITUTE(TRIM(E501),",","."))+1,99),"."),_xlfn.NUMBERVALUE(SUBSTITUTE(TRIM(E501),",","."),".")),0)))

Sheet Базовые времена
A1: Бассейн | B1: Пол | C1: Дистанция | D1: Базовое время, с | E1: Базовое время
A2: 25 м | B2: Мужчины | C2: 50 м вольный стиль | D2: 19.9 | E2: =IF(INT(ROUND(D2*100,0)/6000)>0,INT(ROUND(D2*100,0)/6000)&":"&RIGHT("0"&INT(MOD(ROUND(D2*100,0),6000)/100),2),INT(MOD(ROUND(D2*100,0),6000)/100))&"."&RIGHT("0"&MOD(ROUND(D2*100,0),100),2) -> 19.90
A3: 25 м | B3: Мужчины | C3: 100 м вольный стиль | D3: 44.84 | E3: =IF(INT(ROUND(D3*100,0)/6000)>0,INT(ROUND(D3*100,0)/6000)&":"&RIGHT("0"&INT(MOD(ROUND(D3*100,0),6000)/100),2),INT(MOD(ROUND(D3*100,0),6000)/100))&"."&RIGHT("0"&MOD(ROUND(D3*100,0),100),2) -> 44.84
A4: 25 м | B4: Мужчины | C4: 200 м вольный стиль | D4: 98.61 | E4: =IF(INT(ROUND(D4*100,0)/6000)>0,INT(ROUND(D4*100,0)/6000)&":"&RIGHT("0"&INT(MOD(ROUND(D4*100,0),6000)/100),2),INT(MOD(ROUND(D4*100,0),6000)/100))&"."&RIGHT("0"&MOD(ROUND(D4*100,0),100),2) -> 1:38.61
A5: 25 м | B5: Мужчины | C5: 400 м вольный стиль | D5: 212.25 | E5: =IF(INT(ROUND(D5*100,0)/6000)>0,INT(ROUND(D5*100,0)/6000)&":"&RIGHT("0"&INT(MOD(ROUND(D5*100,0),6000)/100),2),INT(MOD(ROUND(D5*100,0),6000)/100))&"."&RIGHT("0"&MOD(ROUND(D5*100,0),100),2) -> 3:32.25
A6: 25 м | B6: Мужчины | C6: 800 м вольный стиль | D6: 440.46 | E6: =IF(INT(ROUND(D6*100,0)/6000)>0,INT(ROUND(D6*100,0)/6000)&":"&RIGHT("0"&INT(MOD(ROUND(D6*100,0),6000)/100),2),INT(MOD(ROUND(D6*100,0),6000)/100))&"."&RIGHT("0"&MOD(ROUND(D6*100,0),100),2) -> 7:20.46
A7: 25 м | B7: Мужчины | C7: 1500 м вольный стиль | D7: 846.88 | E7: =IF(INT(ROUND(D7*100,0)/6000)>0,INT(ROUND(D7*100,0)/6000)&":"&RIGHT("0"&INT(MOD(ROUND(D7*100,0),6000)/100),2),INT(MOD(ROUND(D7*100,0),6000)/100))&"."&RIGHT("0"&MOD(ROUND(D7*100,0),100),2) -> 14:06.88
A8: 25 м | B8: Мужчины | C8: 50 м на спине | D8: 22.11 | E8: =IF(INT(ROUND(D8*100,0)/6000)>0,INT(ROUND(D8*100,0)/6000)&":"&RIGHT("0"&INT(MOD(ROUND(D8*100,0),6000)/100),2),INT(MOD(ROUND(D8*100,0),6000)/100))&"."&RIGHT("0"&MOD(ROUND(D8*100,0),100),2) -> 22.11
A9: 25 м | B9: Мужчины | C9: 100 м на спине | D9: 48.16 | E9: =IF(INT(ROUND(D9*100,0)/6000)>0,INT(ROUND(D9*100,0)/6000)&":"&RIGHT("0"&INT(MOD(ROUND(D9*100,0),6000)/100),2),INT(MOD(ROUND(D9*100,0),6000)/100))&"."&RIGHT("0"&MOD(ROUND(D9*100,0),100),2) -> 48.16
A10: 25 м | B10: Мужчины | C10: 200 м на спине | D10: 105.12 | E10: =IF(INT(ROUND(D10*100,0)/6000)>0,INT(ROUND(D10*100,0)/6000)&":"&RIGHT("0"&INT(MOD(ROUND(D10*100,0),6000)/100),2),INT(MOD(ROUND(D10*100,0),6000)/100))&"."&RIGHT("0"&MOD(ROUND(D10*100,0),100),2) -> 1:45.12
A11: 25 м | B11: Мужчины | C11: 50 м брасс | D11: 24.95 | E11: =IF(INT(ROUND(D11*100,0)/6000)>0,INT(ROUND(D11*100,0)/6000)&":"&RIGHT("0"&INT(MOD(ROUND(D11*100,0),6000)/100),2),INT(MOD(ROUND(D11*100,0),6000)/100))&"."&RIGHT("0"&MOD(ROUND(D11*100,0),100),2) -> 24.95
A12: 25 м | B12: Мужчины | C12: 100 м брасс | D12: 55.28 | E12: =IF(INT(ROUND(D12*100,0)/6000)>0,INT(ROUND(D12*100,0)/6000)&":"&RIGHT("0"&INT(MOD(ROUND(D12*100,0),6000)/100),2),INT(MOD(ROUND(D12*100,0),6000)/100))&"."&RIGHT("0"&MOD(ROUND(D12*100,0),100),2) -> 55.28
A13: 25 м | B13: Мужчины | C13: 200 м брасс | D13: 119.52 | E13: =IF(INT(ROUND(D13*100,0)/6000)>0,INT(ROUND(D13*100,0)/6000)&":"&RIGHT("0"&INT(MOD(ROUND(D13*100,0),6000)/100),2),INT(MOD(ROUND(D13*100,0),6000)/100))&"."&RIGHT("0"&MOD(ROUND(D13*100,0),100),2) -> 1:59.52
... A71: 50 м | B71: Женщины | C71: 400 м комплекс | D71: 263.65 | E71: =IF(INT(ROUND(D71*100,0)/6000)>0,INT(ROUND(D71*100,0)/6000)&":"&RIGHT("0"&INT(MOD(ROUND(D71*100,0),6000)/100),2),INT(MOD(ROUND(D71*100,0),6000)/100))&"."&RIGHT("0"&MOD(ROUND(D71*100,0),100),2) -> 4:23.65
A73: Источник: World Aquatics Points — Base Times SCM and LCM. Редакции: SCM (25 м) 2026 действует 2026-09-01 — 2027-08-31; LCM (50 м) 2026 действует 2026-01-01 — 2026-12-31.
A74: https://resources.fina.org/fina/document/2026/09/05/9b48fb98-233c-4ce9-b67b-bc6163319bbd/Points-Base-times-SCM-and-LCM-2026_09.2026.pdf
A75: Когда редакция истечёт, замените числа в столбце D — остальные листы пересчитаются сами.

Sheet Списки
A1: Бассейн | B1: Пол | C1: Дистанция | D1: Минуты | E1: Секунды | F1: Сотые | G1: Очки
A2: 25 м | B2: Мужчины | C2: 50 м вольный стиль | D2: 0 | E2: 0 | F2: 0 | G2: 1000
A3: 50 м | B3: Женщины | C3: 100 м вольный стиль | D3: 1 | E3: 1 | F3: 1 | G3: 990
C4: 200 м вольный стиль | D4: 2 | E4: 2 | F4: 2 | G4: 980
C5: 400 м вольный стиль | D5: 3 | E5: 3 | F5: 3 | G5: 970
C6: 800 м вольный стиль | D6: 4 | E6: 4 | F6: 4 | G6: 960
C7: 1500 м вольный стиль | D7: 5 | E7: 5 | F7: 5 | G7: 950
C8: 50 м на спине | D8: 6 | E8: 6 | F8: 6 | G8: 940
C9: 100 м на спине | D9: 7 | E9: 7 | F9: 7 | G9: 930
C10: 200 м на спине | D10: 8 | E10: 8 | F10: 8 | G10: 920
C11: 50 м брасс | D11: 9 | E11: 9 | F11: 9 | G11: 910
C12: 100 м брасс | D12: 10 | E12: 10 | F12: 10 | G12: 900
C13: 200 м брасс | D13: 11 | E13: 11 | F13: 11 | G13: 890
C14: 50 м баттерфляй | D14: 12 | E14: 12 | F14: 12 | G14: 880
C15: 100 м баттерфляй | D15: 13 | E15: 13 | F15: 13 | G15: 870
... C19: 400 м комплекс | D19: 17 | E19: 17 | F19: 17 | G19: 830
D20: 18 | E20: 18 | F20: 18 | G20: 820
D21: 19 | E21: 19 | F21: 19 | G21: 810
D22: 20 | E22: 20 | F22: 20 | G22: 800
D23: 21 | E23: 21 | F23: 21 | G23: 790
D24: 22 | E24: 22 | F24: 22 | G24: 780
D25: 23 | E25: 23 | F25: 23 | G25: 770
D26: 24 | E26: 24 | F26: 24 | G26: 760
D27: 25 | E27: 25 | F27: 25 | G27: 750
D28: 26 | E28: 26 | F28: 26 | G28: 740
D29: 27 | E29: 27 | F29: 27 | G29: 730
D30: 28 | E30: 28 | F30: 28 | G30: 720
D31: 29 | E31: 29 | F31: 29 | G31: 710
D32: 30 | E32: 30 | F32: 30 | G32: 700
E33: 31 | F33: 31 | G33: 690
E34: 32 | F34: 32 | G34: 680
E35: 33 | F35: 33 | G35: 670
E36: 34 | F36: 34 | G36: 660
E37: 35 | F37: 35 | G37: 650
E38: 36 | F38: 36 | G38: 640
E39: 37 | F39: 37 | G39: 630
E40: 38 | F40: 38 | G40: 620
E41: 39 | F41: 39 | G41: 610
E42: 40 | F42: 40 | G42: 600
E43: 41 | F43: 41 | G43: 590
...
